Workbook

Sheet Relación Componentes PAT1
A1: REPORTE COMPONENTES PAT1
A5: SPCC | B5: SISTEMA | C5: NOMBRE COMPONENTE | D5: HORAS LÍMITE | E5: HORAS ACTUALES | F5: ÚLTIMO CAMBIO | G5: PRÓXIMO CAMBIO | H5: NÚMERO SERIE | I5: NUEVO | J5: REPARADO | K5: AC
A6: PAT1 | B6: MANTENIMIENTO | C6: HRS. ACUMULADAS OVERHAUL | D6: 50000 | E6: 13559 | F6: 45366 | G6: 11495 | H6: JOY GLOBAL - 4100573765
A7: PAT1 | B7: MANTENIMIENTO | C7: ASIENTO OPERADOR | D7: 15000 | E7: 13559 | F7: 45366 | G7: 46270 | H7: R93433F1-NUEVO JOY-4100552381 | I7: 6600
A8: PAT1 | B8: SISTEMA DE EMPUJE | C8: CAJA DE EMPUJE | D8: 25000 | E8: 13559 | F8: 45366 | G8: 18-ene-28 | H8: CROTRAT202-TMMO-CARCASA NUEVA | J8: 187206.29
A9: PAT1 | B9: SISTEMA DE EMPUJE | C9: CILINDRO DE ESCALERA RH | D9: 10000 | E9: 13559 | F9: 45366 | G9: 29-dic-25 | H9: NUEVO JOYGLOBAL R. 8435125 | I9: 3165.1367
A10: PAT1 | B10: SISTEMA DE EMPUJE | C10: CILINDRO DE ESCALERA LH | D10: 10000 | E10: 13559 | F10: 45366 | G10: 29-dic-25 | H10: NUEVO JOYGLOBAL R. 8435125 | I10: 3165.1367
A11: PAT1 | B11: SISTEMA DE EMPUJE | C11: EJE DE EMPUJE - SHIPER SHAFT | D11: 50000 | E11: 13559 | F11: 45366 | G11: 11495 | H11: NUEVO JOY GLOBAL R 8434227 | I11: 145757.92
A12: PAT1 | B12: SISTEMA DE EMPUJE | C12: ENGRANAJE DE EMPUJE | D12: 50000 | E12: 13559 | F12: 45366 | G12: 11495 | H12: NUEVO-JOYGLOBAL-R.8434227 | I12: 154040
A13: PAT1 | B13: SISTEMA DE EMPUJE | C13: PIÑONES DE EMPUJE | D13: 25000 | E13: 13559 | F13: 45366 | G13: 18-ene-28 | H13: NUEVO JOY GLOBAL - R 8434227 | I13: 119660
A14: PAT1 | B14: SISTEMA DE EMPUJE | C14: BRAZO DE CUCHARON | D14: 25000 | E14: 13559 | F14: 45366 | G14: 18-ene-28 | H14: HANDIPT201-USITEM | J14: 296340
A15: PAT1 | B15: SISTEMA DE EMPUJE | C15: MONTURA DERECHA | D15: 25000 | E15: 13559 | F15: 45366 | G15: 18-ene-28 | H15: SADBLOT205-KOMATSU | J15: 123179.97
A16: PAT1 | B16: SISTEMA DE EMPUJE | C16: MONTURA IZQUIERDA | D16: 25000 | E16: 13559 | F16: 45366 | G16: 18-ene-28 | H16: SADBLOT214-KOMATSU | J16: 123179.97
A17: PAT1 | B17: SISTEMA DE EMPUJE | C17: CUCHARON - PIN Y BUJE DE OREJA | D17: 5000 | E17: 777 | F17: 46149 | G17: 22-ene-27 | H17: NUEVO-KMMP | I17: 20474.6
A18: PAT1 | B18: SISTEMA DE EMPUJE | C18: CUCHARON | D18: 5000 | E18: 3665 | F18: 45941 | G18: 31-ago-26 | H18: DIPPERT208 | J18: 541610.92
A19: PAT1 | B19: SISTEMA DE EMPUJE | C19: CUCHARON - COMPUERTA | D19: 2500 | E19: 3665 | F19: 45941 | G19: 28-abr-26 | H19: DIPDOOT208-USITEM | J19: 0
A20: PAT1 | B20: SISTEMA DE EMPUJE | C20: CUCHARON - BARRETON | D20: 1250 | E20: 439 | F20: 46165 | G20: 04-ago-26 | H20: NUEVO-KOMATSU | I20: 61862.56
A21: PAT1 | B21: SISTEMA DE EMPUJE | C21: CUCHARON - ESPADA | D21: 1250 | E21: 439 | F21: 46165 | G21: 04-ago-26 | H21: NUEVO -KOMATSU | I21: 0
A22: PAT1 | B22: SISTEMA DE EMPUJE | C22: CUCHARON - FRENO DE COMPUERTA RH | D22: 5000 | E22: 3665 | F22: 45941 | G22: 31-ago-26 | H22: BRDIDOT258 - CASTECH | J22: 36446.5
A23: PAT1 | B23: SISTEMA DE EMPUJE | C23: CUCHARON - FRENO DE COMPUERTA LH | D23: 5000 | E23: 3665 | F23: 45941 | G23: 31-ago-26 | H23: BRDIDOT254 - CASTECH | J23: 36446.5
A24: PAT1 | B24: SISTEMA DE EMPUJE | C24: FRENO DE EMPUJE | D24: 7000 | E24: 6525 | F24: 17-abr-25 | G24: 46222 | H24: CROBRAT201-TMMO | J24: 10479.86
A25: PAT1 | B25: SISTEMA DE EMPUJE | C25: FAJAS DE EMPUJE | D25: 6000 | E25: 3229 | F25: 45976 | G25: 46336 | H25: NUEVO | I25: 4556.03
A26: PAT1 | B26: SISTEMA DE GIRO | C26: CAJA DE GIRO DELANTERO | D26: 25000 | E26: 13559 | F26: 45366 | G26: 18-ene-28 | H26: SWITRAT200-TMMO | J26: 246575.83
A27: PAT1 | B27: SISTEMA DE GIRO | C27: CAJA DE GIRO POSTERIOR | D27: 25000 | E27: 13499 | F27: 01-abr-24 | G27: 21-ene-28 | H27: SWITRAT207-TMMO | J27: 246575.83
A28: PAT1 | B28: SISTEMA DE GIRO | C28: EJE DE GIRO DELANTERO | D28: 25000 | E28: 6774 | F28: 04-abr-25 | G28: 22-dic-28 | H28: SHASWIT208-TMMO | I28: 111515.88
A29: PAT1 | B29: SISTEMA DE GIRO | C29: EJE DE GIRO POSTERIOR | D29: 25000 | E29: 13559 | F29: 45366 | G29: 18-ene-28 | H29: SHASWIT288 JOYGLOBAL4100555988 | I29: 111515.88
A30: PAT1 | B30: SISTEMA DE GIRO | C30: FRENO DE GIRO DELANTERO | D30: 7000 | E30: 5229 | F30: 45835 | G30: 46286 | H30: BRASWIT201-TMMO | J30: 7936.58
A31: PAT1 | B31: SISTEMA DE GIRO | C31: FRENO DE GIRO POSTERIOR | D31: 7000 | E31: 5229 | F31: 45835 | G31: 46286 | H31: BRASWIT202 | J31: 7936.58
A32: PAT1 | B32: SISTEMA DE GIRO | C32: PIN CENTRAL DE TORNAMESA | D32: 50000 | E32: 13559 | F32: 45366 | G32: 11495 | H32: NUEVO JOY GLOBAL 4100540786 | I32: 0
A33: PAT1 | B33: SISTEMA DE GIRO | C33: RODILLOS DE TORNAMESA | D33: 50000 | E33: 13559 | F33: 45366 | G33: 11495 | H33: NUEVO JOYGLOBAL 4100540786 | I33: 0
A34: PAT1 | B34: SISTEMA DE GIRO | C34: ENGRANAJE DE TORNAMEZA | D34: 50000 | E34: 13559 | F34: 45366 | G34: 11495 | H34: NUEVO JOY GLOBAL - 4100540769 | I34: 0
A35: PAT1 | B35: SISTEMA DE GIRO | C35: AJUSTE TUERCA PIN CENTRAL | D35: 5000 | E35: 13559 | F35: 45366 | G35: 23-abr-25 | I35: 0
A36: PAT1 | B36: SISTEMA DE GIRO | C36: INSP. DE AJUSTE TUERCA PIN CENTRAL | D36: 3000 | E36: 7603 | F36: 45699 | G36: 45968 | I36: 0
A37: PAT1 | B37: SISTEMA DE IZAR | C37: CAJA DE IZAR | D37: 25000 | E37: 13559 | F37: 45366 | G37: 18-ene-28 | H37: HOIGEAT211-TMMO | J37: 278998.71
A38: PAT1 | B38: SISTEMA DE IZAR | C38: BOMBA ACEITE CAJA IZAR | D38: 25000 | E38: 13559 | F38: 45366 | G38: 18-ene-28 | H38: HOIPUMT212 - KMC | I38: 29594.93
A39: PAT1 | B39: SISTEMA DE IZAR | C39: TAMBOR DE IZAR | D39: 25000 | E39: 13559 | F39: 45366 | G39: 18-ene-28 | H39: DRUHOIT203 -JOY GLOBAL 4100519354 | J39: 340389.81
A40: PAT1 | B40: SISTEMA DE IZAR | C40: RETENES DE TAMBOR DE IZAR | D40: 12500 | E40: 13559 | F40: 45366 | G40: 46145 | H40: NUEVO JOY 4100519354 | I40: 0
A41: PAT1 | B41: SISTEMA DE IZAR | C41: PLUMA | D41: 50000 | E41: 13559 | F41: 45366 | G41: 11495 | H41: BOOMT203 USITEM | J41: 158691.91
A42: PAT1 | B42: SISTEMA DE IZAR | C42: POLEAS DE PLUMA | D42: 25000 | E42: 9516 | F42: 45593 | G42: 07-ago-28 | H42: SHEBOOT238-239 | J42: 140797.2
A43: PAT1 | B43: SISTEMA DE IZAR | C43: CABLES DE SUSPENSION | D43: 25000 | E43: 2586 | F43: 27-dic-25 | G43: 47318 | H43: BOSUCAT228 -NUEVO-KOMATSU | I43: 113844.2
...

Sheet BASE_COMPONENTES
A1: ID_COMPONENTE | B1: EQUIPO | C1: FLOTA | D1: SISTEMA | E1: CODIGO_COMPONENTE | F1: NOMBRE_COMPONENTE | G1: HORAS_LIMITE | H1: HORAS_ACTUALES | I1: ULTIMO_CAMBIO | J1: PROXIMO_CAMBIO | K1: NUMERO_SERIE | L1: ITEM_MANTENIBLE | M1: OPCION_COMPONENTE | N1: COMENTARIOS
A2: 1 | B2: PAT1 | C2: 4100A | D2: MANTENIMIENTO | E2: HRS_ACUM_OVERHAUL | F2: HRS. ACUMULADAS OVERHAUL | G2: 50000 | H2: 13559 | I2: 45366 | J2: 11495 | L2: SI | M2: REPARAR
A3: 2 | B3: PAT1 | C3: 4100A | D3: MANTENIMIENTO | E3: R93433F1 | F3: ASIENTO OPERADOR | G3: 15000 | H3: 13559 | I3: 45366 | J3: 46270 | L3: NO | M3: NUEVO
A4: 3 | B4: PAT1 | C4: 4100A | D4: SISTEMA DE EMPUJE | E4: CIL_ESCALERA_RH | F4: CILINDRO DE ESCALERA RH | G4: 10000 | H4: 13559 | I4: 45366 | J4: 46020 | L4: NO | M4: NUEVO
A5: 4 | B5: PAT1 | C5: 4100A | D5: SISTEMA DE EMPUJE | E5: CROTRAT202 | F5: CAJA DE EMPUJE | G5: 25000 | H5: 13559 | I5: 45366 | J5: 46770 | L5: SI | M5: REPARAR
A6: 3 | B6: PAT1 | C6: 4100A | D6: SISTEMA DE EMPUJE | E6: CIL_ESCALERA_LH | F6: CILINDRO DE ESCALERA LH | G6: 10000 | H6: 13559 | I6: 45366 | J6: 46020 | L6: NO | M6: NUEVO
A7: 5 | B7: PAT1 | C7: 4100A | D7: SISTEMA DE EMPUJE | E7: EJE_EMPUJE_SHIPER_SHAFT | F7: EJE DE EMPUJE - SHIPER SHAFT (PN: R3989D2/R3989D3) | G7: 50000 | H7: 13559 | I7: 45366 | J7: 11495 | L7: NO | M7: NUEVO
A8: 6 | B8: PAT1 | C8: 4100A | D8: SISTEMA DE EMPUJE | E8: ENGRANAJE_EMPUJE | F8: ENGRANAJE DE EMPUJE | G8: 50000 | H8: 13559 | I8: 45366 | J8: 11495 | L8: NO | M8: NUEVO
A9: 7 | B9: PAT1 | C9: 4100A | D9: SISTEMA DE EMPUJE | E9: PINIONES_EMPUJE | F9: PIÑONES DE EMPUJE | G9: 25000 | H9: 13559 | I9: 45366 | J9: 46770 | L9: NO | M9: NUEVO
A10: 8 | B10: PAT1 | C10: 4100A | D10: SISTEMA DE EMPUJE | E10: HANDIPT201 | F10: BRAZOS DE EMPUJE | G10: 25000 | H10: 13559 | I10: 45366 | J10: 46770 | L10: SI | M10: REPARAR
A11: 9 | B11: PAT1 | C11: 4100A | D11: SISTEMA DE EMPUJE | E11: SADBLOT205 | F11: MONTURA DERECHA | G11: 25000 | H11: 13559 | I11: 45366 | J11: 46770 | L11: SI | M11: REPARAR
A12: 9 | B12: PAT1 | C12: 4100A | D12: SISTEMA DE EMPUJE | E12: SADBLOT214 | F12: MONTURA IZQUIERDA | G12: 25000 | H12: 13559 | I12: 45366 | J12: 46770 | L12: SI | M12: REPARAR
A13: 10 | B13: PAT1 | C13: 4100A | D13: SISTEMA DE EMPUJE | E13: CUCHARON_PIN_BUJE_OREJA | F13: CUCHARON - PIN Y BUJE DE OREJA | G13: 5000 | H13: 777 | I13: 46149 | J13: 46409 | L13: NO | M13: NUEVO
... A63: 1 | B63: PAT4 | C63: 4100A | D63: MANTENIMIENTO | E63: HRS_ACUM_OVERHAUL | F63: HRS. ACUMULADAS OVERHAUL | G63: 50000 | H63: 23023 | I63: 44810 | J63: 11022 | L63: SI | M63: REPARAR
A64: 2 | B64: PAT4 | C64: 4100A | D64: MANTENIMIENTO | E64: ASIENTO_OPERADOR | F64: ASIENTO OPERADOR | G64: 15000 | H64: 8677 | I64: 04-dic-24 | J64: 46514 | L64: NO | M64: NUEVO
A65: 4 | B65: PAT4 | C65: 4100A | D65: SISTEMA DE EMPUJE | E65: CROTRAT201 | F65: CAJA DE EMPUJE | G65: 25000 | H65: 5574 | I65: 45806 | J65: 47169 | L65: NO | M65: NUEVO
A66: 3 | B66: PAT4 | C66: 4100A | D66: SISTEMA DE EMPUJE | E66: CILINDRO_ESCALERA_RH | F66: CILINDRO DE ESCALERA RH | G66: 10000 | H66: 9944 | I66: 45553 | J66: 46201 | L66: SI | M66: REPARAR
A67: 3 | B67: PAT4 | C67: 4100A | D67: SISTEMA DE EMPUJE | E67: CILINDRO_ESCALERA_LH | F67: CILINDRO DE ESCALERA LH | G67: 10000 | H67: 9944 | I67: 45553 | J67: 46201 | L67: NO | M67: NUEVO
A68: 5 | B68: PAT4 | C68: 4100A | D68: SISTEMA DE EMPUJE | E68: EJE_EMPUJE_SHIPER_SHAFT | F68: EJE DE EMPUJE - SHIPER SHAFT (PN: R3989D2/R3989D3) | G68: 50000 | H68: 23023 | I68: 44810 | J68: 11022 | L68: NO | M68: NUEVO
A69: 6 | B69: PAT4 | C69: 4100A | D69: SISTEMA DE EMPUJE | E69: ENGRANAJE_EMPUJE | F69: ENGRANAJE DE EMPUJE | G69: 50000 | H69: 23023 | I69: 44810 | J69: 11022 | L69: NO | M69: NUEVO
A70: 7 | B70: PAT4 | C70: 4100A | D70: SISTEMA DE EMPUJE | E70: PINIONES_EMPUJE | F70: PIÑONES DE EMPUJE | G70: 25000 | H70: 23023 | I70: 44810 | J70: 46297 | L70: NO | M70: NUEVO
A71: 8 | B71: PAT4 | C71: 4100A | D71: SISTEMA DE EMPUJE | E71: HANDIPT200 | F71: BRAZOS DE EMPUJE | G71: 25000 | H71: 23023 | I71: 44810 | J71: 46297 | L71: SI | M71: REPARAR
A72: 9 | B72: PAT4 | C72: 4100A | D72: SISTEMA DE EMPUJE | E72: SADBLOT202 | F72: MONTURA DERECHA | G72: 25000 | H72: 23023 | I72: 44810 | J72: 46297 | L72: SI | M72: REPARAR
A73: 9 | B73: PAT4 | C73: 4100A | D73: SISTEMA DE EMPUJE | E73: SADBLOT203 | F73: MONTURA IZQUIERDA | G73: 25000 | H73: 23023 | I73: 44810 | J73: 46297 | L73: SI | M73: REPARAR
A74: 10 | B74: PAT4 | C74: 4100A | D74: SISTEMA DE EMPUJE | E74: CUCHARON_PIN_BUJE_OREJA | F74: CUCHARON - PIN Y BUJE DE OREJA | G74: 5000 | H74: 653 | I74: 46148 | J74: 28-ene-27 | L74: NO | M74: NUEVO
A75: 11 | B75: PAT4 | C75: 4100A | D75: SISTEMA DE EMPUJE | E75: DIPPERT201 | F75: CUCHARON | G75: 5000 | H75: 653 | I75: 46148 | J75: 28-ene-27 | L75: SI | M75: REPARAR
A76: 12 | B76: PAT4 | C76: 4100A | D76: SISTEMA DE EMPUJE | E76: DIPDOOT201 | F76: CUCHARON - COMPUERTA | G76: 2500 | H76: 653 | I76: 46148 | J76: 46290 | L76: SI | M76: REPARAR
A77: 13 | B77: PAT4 | C77: 4100A | D77: SISTEMA DE EMPUJE | E77: CUCHARON_BARRETON | F77: CUCHARON - BARRETON | G77: 1250 | H77: 653 | I77: 46148 | J77: 46228 | L77: SI | M77: REPARAR_O_NUEVO
A78: 14 | B78: PAT4 | C78: 4100A | D78: SISTEMA DE EMPUJE | E78: CUCHARON_ESPADA | F78: CUCHARON - ESPADA | G78: 1250 | H78: 653 | I78: 46148 | J78: 46228 | L78: NO | M78: NUEVO
A79: 15 | B79: PAT4 | C79: 4100A | D79: SISTEMA DE EMPUJE | E79: BRDIDOT274 | F79: FRENO DE COMPUERTA DERECHO | G79: 5000 | H79: 653 | I79: 46148 | J79: 28-ene-27 | L79: SI | M79: REPARAR_O_NUEVO
A80: 15 | B80: PAT4 | C80: 4100A | D80: SISTEMA DE EMPUJE | E80: BRDIDOT275 | F80: FRENO DE COMPUERTA IZQUIERDO | G80: 5000 | H80: 653 | I80: 46148 | J80: 28-ene-27 | L80: SI | M80: REPARAR_O_NUEVO
A81: 16 | B81: PAT4 | C81: 4100A | D81: SISTEMA DE EMPUJE | E81: CROBRAT207 | F81: FRENO DE EMPUJE | G81: 7000 | H81: 6835 | I81: 45735 | J81: 46206 | L81: SI | M81: REPARAR
A82: 17 | B82: PAT4 | C82: 4100A | D82: SISTEMA DE EMPUJE | E82: FAJAS_EMPUJE | F82: FAJAS DE EMPUJE | G82: 6000 | H82: 11813 | I82: 45449 | J82: 45907 | L82: NO | M82: NUEVO
A83: 18 | B83: PAT4 | C83: 4100A | D83: SISTEMA DE GIRO | E83: SWITRAT220 | F83: CAJA DE GIRO DELANTERO | G83: 25000 | H83: 23023 | I83: 44810 | J83: 46297 | L83: SI | M83: REPARAR
A84: 18 | B84: PAT4 | C84: 4100A | D84: SISTEMA DE GIRO | E84: SWITRAT206 | F84: CAJA DE GIRO POSTERIOR | G84: 25000 | H84: 22799 | I84: 44828 | J84: 46308 | L84: SI | M84: REPARAR
A85: 19 | B85: PAT4 | C85: 4100A | D85: SISTEMA DE GIRO | E85: SHASWIT254 | F85: EJE DE GIRO DELANTERO | G85: 25000 | H85: 23023 | I85: 44810 | J85: 46297 | L85: SI | M85: REPARAR_O_NUEVO
A86: 19 | B86: PAT4 | C86: 4100A | D86: SISTEMA DE GIRO | E86: SHASWIT202 | F86: EJE DE GIRO POSTERIOR | G86: 25000 | H86: 23023 | I86: 44810 | J86: 46297 | L86: SI | M86: REPARAR_O_NUEVO
A87: 20 | B87: PAT4 | C87: 4100A | D87: SISTEMA DE GIRO | E87: BRASWIT228 | F87: FRENO DE GIRO DELANTERO | G87: 7000 | H87: 7338 | I87: 45707 | J87: 46181 | L87: SI | M87: REPARAR
A88: 20 | B88: PAT4 | C88: 4100A | D88: SISTEMA DE GIRO | E88: BRASWIT235 | F88: FRENO DE GIRO POSTERIOR | G88: 7000 | H88: 839 | I88: 15-abr-26 | J88: 29-abr-27 | L88: SI | M88: REPARAR
A89: 21 | B89: PAT4 | C89: 4100A | D89: SISTEMA DE GIRO | E89: PIN_CENTRAL_TORNAMESA | F89: PIN CENTRAL DE TORNAMESA | G89: 50000 | H89: 23023 | I89: 44810 | J89: 11022 | L89: NO | M89: NUEVO
...

Sheet BASE_COSTOS
A1: ID_COMPONENTE | B1: NOMBRE_COMPONENTE | C1: COSTO_COMPONENTE_NUEVO | D1: COSTO_REPARACION | E1: COSTO_MATERIAL_REP_INTERNA | F1: PROVEEDOR | G1: LEAD_TIME_COMPRA_DIAS | H1: TIEMPO_REPARACION_DIAS | I1: TIPO_REPARACION | J1: CLASE_COSTO_COMPONENTE_NUEVO | K1: DESC_CLASE_COSTO_COMPONENTE_NUEVO | L1: CLASE_COSTO_MATERIAL_REP_INTERNA | M1: DESC_CLASE_COSTO_MATERIAL_REP_INTERNA | N1: CLASE_COSTO_REP_EXTERNA | O1: DESC_CLASE_COSTO_REP_EXTERNA | P1: CLASE_COSTO_REP_INTERNA | Q1: DESC_CLASE_COSTO_REP_INTERNA | R1: COMENTARIOS
A2: 1 | B2: =VLOOKUP(A2,BASE_COMPONENTES!$A$2:$G$62,6,FALSE) -> HRS. ACUMULADAS OVERHAUL | F2: KOMATSU | G2: 0 | H2: 90 | I2: INTERNA | J2: 72403348 | K2: REFACCCIONES PARA MAQ PESADA | L2: 72403348 | M2: REFACCCIONES PARA MAQ PESADA | N2: 72403398 | O2: REP EQUIPO FUERA UNIDAD | P2: 72504416 | Q2: 72504416 SERVICIOS CONTRATISTAS REPARACION
A3: 2 | B3: =VLOOKUP(A3,BASE_COMPONENTES!$A$2:$G$62,6,FALSE) -> ASIENTO OPERADOR | C3: 6600 | F3: KOMATSU | G3: 0 | H3: 0 | I3: EXTERNA | J3: 72403348 | K3: REFACCCIONES PARA MAQ PESADA | L3: 72403348 | M3: REFACCCIONES PARA MAQ PESADA | N3: 72403398 | O3: REP EQUIPO FUERA UNIDAD | P3: 72504416 | Q3: 72504416 SERVICIOS CONTRATISTAS REPARACION
A4: 3 | B4: =VLOOKUP(A4,BASE_COMPONENTES!$A$2:$G$62,6,FALSE) -> CILINDRO DE ESCALERA RH | C4: 3165.1367 | D4: 1200 | F4: KOMATSU | G4: 0 | H4: 30 | I4: EXTERNA | J4: 72403348 | K4: REFACCCIONES PARA MAQ PESADA | L4: 72403348 | M4: REFACCCIONES PARA MAQ PESADA | N4: 72403398 | O4: REP EQUIPO FUERA UNIDAD | P4: 72504416 | Q4: 72504416 SERVICIOS CONTRATISTAS REPARACION
A5: 4 | B5: =VLOOKUP(A5,BASE_COMPONENTES!$A$2:$G$62,6,FALSE) -> CAJA DE EMPUJE | E5: 187206.29 | F5: KOMATSU | G5: 0 | H5: 30 | I5: INTERNA | J5: 72403348 | K5: REFACCCIONES PARA MAQ PESADA | L5: 72403348 | M5: REFACCCIONES PARA MAQ PESADA | N5: 72403398 | O5: REP EQUIPO FUERA UNIDAD | P5: 72504416 | Q5: 72504416 SERVICIOS CONTRATISTAS REPARACION
A6: 5 | B6: =VLOOKUP(A6,BASE_COMPONENTES!$A$2:$G$62,6,FALSE) -> EJE DE EMPUJE - SHIPER SHAFT (PN: R3989D2/R3989D3) | C6: 145757.92 | F6: KOMATSU | G6: 0 | H6: 0 | I6: EXTERNA | J6: 72403348 | K6: REFACCCIONES PARA MAQ PESADA | L6: 72403348 | M6: REFACCCIONES PARA MAQ PESADA | N6: 72403398 | O6: REP EQUIPO FUERA UNIDAD | P6: 72504416 | Q6: 72504416 SERVICIOS CONTRATISTAS REPARACION
A7: 6 | B7: =VLOOKUP(A7,BASE_COMPONENTES!$A$2:$G$62,6,FALSE) -> ENGRANAJE DE EMPUJE | C7: 154040 | F7: KOMATSU | G7: 0 | H7: 0 | I7: EXTERNA | J7: 72403348 | K7: REFACCCIONES PARA MAQ PESADA | L7: 72403348 | M7: REFACCCIONES PARA MAQ PESADA | N7: 72403398 | O7: REP EQUIPO FUERA UNIDAD | P7: 72504416 | Q7: 72504416 SERVICIOS CONTRATISTAS REPARACION
A8: 7 | B8: =VLOOKUP(A8,BASE_COMPONENTES!$A$2:$G$62,6,FALSE) -> PIÑONES DE EMPUJE | C8: 119660 | F8: KOMATSU | G8: 0 | H8: 0 | I8: EXTERNA | J8: 72403348 | K8: REFACCCIONES PARA MAQ PESADA | L8: 72403348 | M8: REFACCCIONES PARA MAQ PESADA | N8: 72403398 | O8: REP EQUIPO FUERA UNIDAD | P8: 72504416 | Q8: 72504416 SERVICIOS CONTRATISTAS REPARACION
A9: 8 | B9: =VLOOKUP(A9,BASE_COMPONENTES!$A$2:$G$62,6,FALSE) -> BRAZOS DE EMPUJE | D9: 87000 | E9: =296340-D9 -> 209340 | F9: KOMATSU | G9: 0 | H9: 45 | I9: INTERNA | J9: 72403348 | K9: REFACCCIONES PARA MAQ PESADA | L9: 72403348 | M9: REFACCCIONES PARA MAQ PESADA | N9: 72403398 | O9: REP EQUIPO FUERA UNIDAD | P9: 72504416 | Q9: 72504416 SERVICIOS CONTRATISTAS REPARACION
A10: 9 | B10: =VLOOKUP(A10,BASE_COMPONENTES!$A$2:$G$62,6,FALSE) -> MONTURA DERECHA | D10: 123179.97 | F10: KOMATSU | G10: 0 | H10: 90 | I10: EXTERNA | J10: 72403348 | K10: REFACCCIONES PARA MAQ PESADA | L10: 72403348 | M10: REFACCCIONES PARA MAQ PESADA | N10: 72403398 | O10: REP EQUIPO FUERA UNIDAD | P10: 72504416 | Q10: 72504416 SERVICIOS CONTRATISTAS REPARACION
A11: 10 | B11: =VLOOKUP(A11,BASE_COMPONENTES!$A$2:$G$62,6,FALSE) -> CUCHARON - PIN Y BUJE DE OREJA | C11: 20474.6 | F11: KOMATSU | G11: 0 | H11: 0 | I11: EXTERNA | J11: 72403348 | K11: REFACCCIONES PARA MAQ PESADA | L11: 72403348 | M11: REFACCCIONES PARA MAQ PESADA | N11: 72403398 | O11: REP EQUIPO FUERA UNIDAD | P11: 72504416 | Q11: 72504416 SERVICIOS CONTRATISTAS REPARACION
A12: 11 | B12: =VLOOKUP(A12,BASE_COMPONENTES!$A$2:$G$62,6,FALSE) -> CUCHARON | D12: 193447.24 | E12: 306543.01 | F12: KOMATSU | G12: 0 | H12: 45 | I12: INTERNA | J12: 72403348 | K12: REFACCCIONES PARA MAQ PESADA | L12: 72403348 | M12: REFACCCIONES PARA MAQ PESADA | N12: 72403398 | O12: REP EQUIPO FUERA UNIDAD | P12: 72504416 | Q12: 72504416 SERVICIOS CONTRATISTAS REPARACION
A13: 12 | B13: =VLOOKUP(A13,BASE_COMPONENTES!$A$2:$G$62,6,FALSE) -> CUCHARON - COMPUERTA | D13: 0 | F13: KOMATSU | G13: 0 | H13: 45 | I13: INTERNA | J13: 72403348 | K13: REFACCCIONES PARA MAQ PESADA | L13: 72403348 | M13: REFACCCIONES PARA MAQ PESADA | N13: 72403398 | O13: REP EQUIPO FUERA UNIDAD | P13: 72504416 | Q13: 72504416 SERVICIOS CONTRATISTAS REPARACION
A14: 13 | B14: =VLOOKUP(A14,BASE_COMPONENTES!$A$2:$G$62,6,FALSE) -> CUCHARON - BARRETON | C14: 61862.56 | D14: 4334 | E14: =10276.31-D14 -> 5942.31 | F14: KOMATSU | G14: 0 | H14: 0 | I14: INTERNA | J14: 72403348 | K14: REFACCCIONES PARA MAQ PESADA | L14: 72403348 | M14: REFACCCIONES PARA MAQ PESADA | N14: 72403398 | O14: REP EQUIPO FUERA UNIDAD | P14: 72504416 | Q14: 72504416 SERVICIOS CONTRATISTAS REPARACION
A15: 14 | B15: =VLOOKUP(A15,BASE_COMPONENTES!$A$2:$G$62,6,FALSE) -> CUCHARON - ESPADA | C15: 4000 | F15: KOMATSU | G15: 0 | H15: 0 | I15: INTERNA | J15: 72403348 | K15: REFACCCIONES PARA MAQ PESADA | L15: 72403348 | M15: REFACCCIONES PARA MAQ PESADA | N15: 72403398 | O15: REP EQUIPO FUERA UNIDAD | P15: 72504416 | Q15: 72504416 SERVICIOS CONTRATISTAS REPARACION
A16: 15 | B16: =VLOOKUP(A16,BASE_COMPONENTES!$A$2:$G$62,6,FALSE) -> FRENO DE COMPUERTA DERECHO | C16: 68000 | D16: 36446.5 | F16: KOMATSU | G16: 0 | H16: 90 | I16: EXTERNA | J16: 72403348 | K16: REFACCCIONES PARA MAQ PESADA | L16: 72403348 | M16: REFACCCIONES PARA MAQ PESADA | N16: 72403398 | O16: REP EQUIPO FUERA UNIDAD | P16: 72504416 | Q16: 72504416 SERVICIOS CONTRATISTAS REPARACION
A17: 16 | B17: =VLOOKUP(A17,BASE_COMPONENTES!$A$2:$G$62,6,FALSE) -> FRENO DE EMPUJE | E17: 10479.86 | F17: KOMATSU | G17: 0 | H17: 0 | I17: INTERNA | J17: 72403348 | K17: REFACCCIONES PARA MAQ PESADA | L17: 72403348 | M17: REFACCCIONES PARA MAQ PESADA | N17: 72403398 | O17: REP EQUIPO FUERA UNIDAD | P17: 72504416 | Q17: 72504416 SERVICIOS CONTRATISTAS REPARACION
A18: 17 | B18: =VLOOKUP(A18,BASE_COMPONENTES!$A$2:$G$62,6,FALSE) -> FAJAS DE EMPUJE | C18: 4556.03 | F18: KOMATSU | G18: 0 | H18: 0 | I18: EXTERNA | J18: 72403348 | K18: REFACCCIONES PARA MAQ PESADA | L18: 72403348 | M18: REFACCCIONES PARA MAQ PESADA | N18: 72403398 | O18: REP EQUIPO FUERA UNIDAD | P18: 72504416 | Q18: 72504416 SERVICIOS CONTRATISTAS REPARACION
A19: 18 | B19: =VLOOKUP(A19,BASE_COMPONENTES!$A$2:$G$62,6,FALSE) -> CAJA DE GIRO DELANTERO | D19: 246575.83 | F19: KOMATSU | G19: 0 | H19: 60 | I19: EXTERNA | J19: 72403348 | K19: REFACCCIONES PARA MAQ PESADA | L19: 72403348 | M19: REFACCCIONES PARA MAQ PESADA | N19: 72403398 | O19: REP EQUIPO FUERA UNIDAD | P19: 72504416 | Q19: 72504416 SERVICIOS CONTRATISTAS REPARACION
A20: 19 | B20: =VLOOKUP(A20,BASE_COMPONENTES!$A$2:$G$62,6,FALSE) -> EJE DE GIRO DELANTERO | C20: 111515.88 | E20: 56297.92 | F20: KOMATSU | G20: 0 | H20: 0 | I20: EXTERNA | J20: 72403348 | K20: REFACCCIONES PARA MAQ PESADA | L20: 72403348 | M20: REFACCCIONES PARA MAQ PESADA | N20: 72403398 | O20: REP EQUIPO FUERA UNIDAD | P20: 72504416 | Q20: 72504416 SERVICIOS CONTRATISTAS REPARACION
A21: 20 | B21: =VLOOKUP(A21,BASE_COMPONENTES!$A$2:$G$62,6,FALSE) -> FRENO DE GIRO DELANTERO | E21: 7936.58 | F21: KOMATSU | G21: 0 | H21: 0 | I21: INTERNA | J21: 72403348 | K21: REFACCCIONES PARA MAQ PESADA | L21: 72403348 | M21: REFACCCIONES PARA MAQ PESADA | N21: 72403398 | O21: REP EQUIPO FUERA UNIDAD | P21: 72504416 | Q21: 72504416 SERVICIOS CONTRATISTAS REPARACION
A22: 21 | B22: =VLOOKUP(A22,BASE_COMPONENTES!$A$2:$G$62,6,FALSE) -> PIN CENTRAL DE TORNAMESA | C22: 0 | F22: KOMATSU | G22: 0 | H22: 0 | I22: EXTERNA | J22: 72403348 | K22: REFACCCIONES PARA MAQ PESADA | L22: 72403348 | M22: REFACCCIONES PARA MAQ PESADA | N22: 72403398 | O22: REP EQUIPO FUERA UNIDAD | P22: 72504416 | Q22: 72504416 SERVICIOS CONTRATISTAS REPARACION
A23: 22 | B23: =VLOOKUP(A23,BASE_COMPONENTES!$A$2:$G$62,6,FALSE) -> RODILLOS DE TORNAMESA | C23: 0 | F23: KOMATSU | G23: 0 | H23: 0 | I23: EXTERNA | J23: 72403348 | K23: REFACCCIONES PARA MAQ PESADA | L23: 72403348 | M23: REFACCCIONES PARA MAQ PESADA | N23: 72403398 | O23: REP EQUIPO FUERA UNIDAD | P23: 72504416 | Q23: 72504416 SERVICIOS CONTRATISTAS REPARACION
A24: 23 | B24: =VLOOKUP(A24,BASE_COMPONENTES!$A$2:$G$62,6,FALSE) -> ENGRANAJE DE TORNAMEZA | C24: 0 | F24: KOMATSU | G24: 0 | H24: 0 | I24: EXTERNA | J24: 72403348 | K24: REFACCCIONES PARA MAQ PESADA | L24: 72403348 | M24: REFACCCIONES PARA MAQ PESADA | N24: 72403398 | O24: REP EQUIPO FUERA UNIDAD | P24: 72504416 | Q24: 72504416 SERVICIOS CONTRATISTAS REPARACION
A25: 24 | B25: =VLOOKUP(A25,BASE_COMPONENTES!$A$2:$G$62,6,FALSE) -> AJUSTE TUERCA PIN CENTRAL | C25: 0 | F25: KOMATSU | G25: 0 | H25: 0 | I25: EXTERNA | J25: 72403348 | K25: REFACCCIONES PARA MAQ PESADA | L25: 72403348 | M25: REFACCCIONES PARA MAQ PESADA | N25: 72403398 | O25: REP EQUIPO FUERA UNIDAD | P25: 72504416 | Q25: 72504416 SERVICIOS CONTRATISTAS REPARACION
A26: 25 | B26: =VLOOKUP(A26,BASE_COMPONENTES!$A$2:$G$62,6,FALSE) -> INSP. DE AJUSTE TUERCA PIN CENTRAL | C26: 0 | F26: KOMATSU | G26: 0 | H26: 0 | I26: INTERNA | J26: 72403348 | K26: REFACCCIONES PARA MAQ PESADA | L26: 72403348 | M26: REFACCCIONES PARA MAQ PESADA | N26: 72403398 | O26: REP EQUIPO FUERA UNIDAD | P26: 72504416 | Q26: 72504416 SERVICIOS CONTRATISTAS REPARACION
A27: 26 | B27: =VLOOKUP(A27,BASE_COMPONENTES!$A$2:$G$62,6,FALSE) -> CAJA DE IZAR | E27: 278998.71 | F27: KOMATSU | G27: 0 | H27: 0 | I27: INTERNA | J27: 72403348 | K27: REFACCCIONES PARA MAQ PESADA | L27: 72403348 | M27: REFACCCIONES PARA MAQ PESADA | N27: 72403398 | O27: REP EQUIPO FUERA UNIDAD | P27: 72504416 | Q27: 72504416 SERVICIOS CONTRATISTAS REPARACION
A28: 27 | B28: =VLOOKUP(A28,BASE_COMPONENTES!$A$2:$G$62,6,FALSE) -> BOMBA ACEITE CAJA IZAR | C28: 29594.93 | F28: KOMATSU | G28: 0 | H28: 0 | I28: EXTERNA | J28: 72403348 | K28: REFACCCIONES PARA MAQ PESADA | L28: 72403348 | M28: REFACCCIONES PARA MAQ PESADA | N28: 72403398 | O28: REP EQUIPO FUERA UNIDAD | P28: 72504416 | Q28: 72504416 SERVICIOS CONTRATISTAS REPARACION
A29: 28 | B29: =VLOOKUP(A29,BASE_COMPONENTES!$A$2:$G$62,6,FALSE) -> TAMBOR DE IZAR | C29: 1250022 | D29: 340389.81 | F29: KOMATSU | G29: 0 | H29: 120 | I29: EXTERNA | J29: 72403348 | K29: REFACCCIONES PARA MAQ PESADA | L29: 72403348 | M29: REFACCCIONES PARA MAQ PESADA | N29: 72403398 | O29: REP EQUIPO FUERA UNIDAD | P29: 72504416 | Q29: 72504416 SERVICIOS CONTRATISTAS REPARACION
A30: 29 | B30: =VLOOKUP(A30,BASE_COMPONENTES!$A$2:$G$62,6,FALSE) -> RETENES DE TAMBOR DE IZAR | C30: 0 | F30: KOMATSU | G30: 0 | H30: 0 | I30: EXTERNA | J30: 72403348 | K30: REFACCCIONES PARA MAQ PESADA | L30: 72403348 | M30: REFACCCIONES PARA MAQ PESADA | N30: 72403398 | O30: REP EQUIPO FUERA UNIDAD | P30: 72504416 | Q30: 72504416 SERVICIOS CONTRATISTAS REPARACION
A31: 30 | B31: =VLOOKUP(A31,BASE_COMPONENTES!$A$2:$G$62,6,FALSE) -> PLUMA | D31: 85000 | E31: 158691.91 | F31: KOMATSU | G31: 0 | H31: 45 | I31: INTERNA | J31: 72403348 | K31: REFACCCIONES PARA MAQ PESADA | L31: 72403348 | M31: REFACCCIONES PARA MAQ PESADA | N31: 72403398 | O31: REP EQUIPO FUERA UNIDAD | P31: 72504416 | Q31: 72504416 SERVICIOS CONTRATISTAS REPARACION
A32: 31 | B32: =VLOOKUP(A32,BASE_COMPONENTES!$A$2:$G$62,6,FALSE) -> POLEAS DE PLUMA | D32: 140797.2 | F32: KOMATSU | G32: 0 | H32: 90 | I32: EXTERNA | J32: 72403348 | K32: REFACCCIONES PARA MAQ PESADA | L32: 72403348 | M32: REFACCCIONES PARA MAQ PESADA | N32: 72403398 | O32: REP EQUIPO FUERA UNIDAD | P32: 72504416 | Q32: 72504416 SERVICIOS CONTRATISTAS REPARACION
A33: 32 | B33: =VLOOKUP(A33,BASE_COMPONENTES!$A$2:$G$62,6,FALSE) -> CABLES DE SUSPENSION | C33: 113844.2 | F33: KOMATSU | G33: 0 | H33: 0 | I33: EXTERNA | J33: 72403348 | K33: REFACCCIONES PARA MAQ PESADA | L33: 72403348 | M33: REFACCCIONES PARA MAQ PESADA | N33: 72403398 | O33: REP EQUIPO FUERA UNIDAD | P33: 72504416 | Q33: 72504416 SERVICIOS CONTRATISTAS REPARACION
A34: 33 | B34: =VLOOKUP(A34,BASE_COMPONENTES!$A$2:$G$62,6,FALSE) -> CABLES DE IZAR | C34: 0 | F34: KOMATSU | G34: 0 | H34: 0 | I34: EXTERNA | J34: 72403348 | K34: REFACCCIONES PARA MAQ PESADA | L34: 72403348 | M34: REFACCCIONES PARA MAQ PESADA | N34: 72403398 | O34: REP EQUIPO FUERA UNIDAD | P34: 72504416 | Q34: 72504416 SERVICIOS CONTRATISTAS REPARACION
A35: 34 | B35: =VLOOKUP(A35,BASE_COMPONENTES!$A$2:$G$62,6,FALSE) -> FRENO DE IZAR DELANTERO | E35: 18803.53 | F35: KOMATSU | G35: 0 | H35: 0 | I35: INTERNA | J35: 72403348 | K35: REFACCCIONES PARA MAQ PESADA | L35: 72403348 | M35: REFACCCIONES PARA MAQ PESADA | N35: 72403398 | O35: REP EQUIPO FUERA UNIDAD | P35: 72504416 | Q35: 72504416 SERVICIOS CONTRATISTAS REPARACION
A36: 35 | B36: =VLOOKUP(A36,BASE_COMPONENTES!$A$2:$G$62,6,FALSE) -> BOMBA DE GRASA 1 GBLANCA UP | C36: 4019.8 | D36: 1004.95 | F36: KOMATSU | G36: 0 | H36: 0 | I36: EXTERNA | J36: 72403348 | K36: REFACCCIONES PARA MAQ PESADA | L36: 72403348 | M36: REFACCCIONES PARA MAQ PESADA | N36: 72403398 | O36: REP EQUIPO FUERA UNIDAD | P36: 72504416 | Q36: 72504416 SERVICIOS CONTRATISTAS REPARACION
A37: 36 | B37: =VLOOKUP(A37,BASE_COMPONENTES!$A$2:$G$62,6,FALSE) -> CAJA DE AVANCE DERECHA | D37: 300000 | F37: KOMATSU | G37: 0 | H37: 60 | I37: EXTERNA | J37: 72403348 | K37: REFACCCIONES PARA MAQ PESADA | L37: 72403348 | M37: REFACCCIONES PARA MAQ PESADA | N37: 72403398 | O37: REP EQUIPO FUERA UNIDAD | P37: 72504416 | Q37: 72504416 SERVICIOS CONTRATISTAS REPARACION
A38: 37 | B38: =VLOOKUP(A38,BASE_COMPONENTES!$A$2:$G$62,6,FALSE) -> FRENO DE AVANCE DERECHO | E38: 9015.43 | F38: KOMATSU | G38: 0 | H38: 0 | I38: INTERNA | J38: 72403348 | K38: REFACCCIONES PARA MAQ PESADA | L38: 72403348 | M38: REFACCCIONES PARA MAQ PESADA | N38: 72403398 | O38: REP EQUIPO FUERA UNIDAD | P38: 72504416 | Q38: 72504416 SERVICIOS CONTRATISTAS REPARACION
A39: 38 | B39: =VLOOKUP(A39,BASE_COMPONENTES!$A$2:$G$62,6,FALSE) -> TUMBLER DERECHO | C39: 139000 | D39: 27973.68 | F39: KOMATSU | G39: 0 | H39: 0 | I39: EXTERNA | J39: 72403348 | K39: REFACCCIONES PARA MAQ PESADA | L39: 72403348 | M39: REFACCCIONES PARA MAQ PESADA | N39: 72403398 | O39: REP EQUIPO FUERA UNIDAD | P39: 72504416 | Q39: 72504416 SERVICIOS CONTRATISTAS REPARACION
A40: 39 | B40: =VLOOKUP(A40,BASE_COMPONENTES!$A$2:$G$62,6,FALSE) -> EJE DE AVANCE DERECHO | C40: 52144.986 | F40: KOMATSU | G40: 0 | H40: 0 | I40: INTERNA | J40: 72403348 | K40: REFACCCIONES PARA MAQ PESADA | L40: 72403348 | M40: REFACCCIONES PARA MAQ PESADA | N40: 72403398 | O40: REP EQUIPO FUERA UNIDAD | P40: 72504416 | Q40: 72504416 SERVICIOS CONTRATISTAS REPARACION
...
